<?xml version="1.0" encoding="UTF-8"?>
<testng-results ignored="0" total="3" passed="1" failed="2" skipped="0">
  <reporter-output>
    <line>
      <![CDATA[Your name is : Jitendra Gupta]]>
    </line>
    <line>
      <![CDATA[Your name is : Akansha Gupta]]>
    </line>
    <line>
      <![CDATA[Your name is : Jitendra Jitendra]]>
    </line>
  </reporter-output>
  <suite started-at="2018-11-02T15:37:40Z" name="Default suite" finished-at="2018-11-02T15:37:40Z" duration-ms="87">
    <groups>
    </groups>
    <test started-at="2018-11-02T15:37:40Z" name="Default test" finished-at="2018-11-02T15:37:40Z" duration-ms="87">
      <class name="testNG_Example.RerunningFailedTestMethod">
        <test-method signature="method4(java.lang.String, java.lang.String)[pri:0, instance:testNG_Example.RerunningFailedTestMethod@445b295b]" started-at="2018-11-02T15:37:40Z" name="method4" data-provider="input" finished-at="2018-11-02T15:37:40Z" duration-ms="24" status="FAIL">
          <params>
            <param index="0">
              <value>
                <![CDATA[Jitendra]]>
              </value>
            </param>
            <param index="1">
              <value>
                <![CDATA[Gupta]]>
              </value>
            </param>
          </params>
          <exception class="java.lang.AssertionError">
            <message>
              <![CDATA[expected [Gupta] but found [Jitendra]]]>
            </message>
            <full-stacktrace>
              <![CDATA[java.lang.AssertionError: expected [Gupta] but found [Jitendra]
at org.testng.Assert.fail(Assert.java:96)
at org.testng.Assert.failNotEquals(Assert.java:776)
at org.testng.Assert.assertEqualsImpl(Assert.java:137)
at org.testng.Assert.assertEquals(Assert.java:118)
at org.testng.Assert.assertEquals(Assert.java:453)
at org.testng.Assert.assertEquals(Assert.java:463)
at testNG_Example.RerunningFailedTestMethod.method4(RerunningFailedTestMethod.java:14)
at java.base/jdk.internal.reflect.NativeMethodAccessorImpl.invoke0(Native Method)
at java.base/jdk.internal.reflect.NativeMethodAccessorImpl.invoke(Unknown Source)
at java.base/jdk.internal.reflect.DelegatingMethodAccessorImpl.invoke(Unknown Source)
at java.base/java.lang.reflect.Method.invoke(Unknown Source)
at org.testng.internal.MethodInvocationHelper.invokeMethod(MethodInvocationHelper.java:124)
at org.testng.internal.Invoker.invokeMethod(Invoker.java:580)
at org.testng.internal.Invoker.invokeTestMethod(Invoker.java:716)
at org.testng.internal.Invoker.invokeTestMethods(Invoker.java:988)
at org.testng.internal.TestMethodWorker.invokeTestMethods(TestMethodWorker.java:125)
at org.testng.internal.TestMethodWorker.run(TestMethodWorker.java:109)
at org.testng.TestRunner.privateRun(TestRunner.java:648)
at org.testng.TestRunner.run(TestRunner.java:505)
at org.testng.SuiteRunner.runTest(SuiteRunner.java:455)
at org.testng.SuiteRunner.runSequentially(SuiteRunner.java:450)
at org.testng.SuiteRunner.privateRun(SuiteRunner.java:415)
at org.testng.SuiteRunner.run(SuiteRunner.java:364)
at org.testng.SuiteRunnerWorker.runSuite(SuiteRunnerWorker.java:52)
at org.testng.SuiteRunnerWorker.run(SuiteRunnerWorker.java:84)
at org.testng.TestNG.runSuitesSequentially(TestNG.java:1208)
at org.testng.TestNG.runSuitesLocally(TestNG.java:1137)
at org.testng.TestNG.runSuites(TestNG.java:1049)
at org.testng.TestNG.run(TestNG.java:1017)
at org.testng.remote.AbstractRemoteTestNG.run(AbstractRemoteTestNG.java:114)
at org.testng.remote.RemoteTestNG.initAndRun(RemoteTestNG.java:251)
at org.testng.remote.RemoteTestNG.main(RemoteTestNG.java:77)
]]>
            </full-stacktrace>
          </exception> <!-- java.lang.AssertionError -->
          <reporter-output>
            <line>
              <![CDATA[Your name is : Jitendra Gupta]]>
            </line>
          </reporter-output>
        </test-method> <!-- method4 -->
        <test-method signature="method4(java.lang.String, java.lang.String)[pri:0, instance:testNG_Example.RerunningFailedTestMethod@445b295b]" started-at="2018-11-02T15:37:40Z" name="method4" data-provider="input" finished-at="2018-11-02T15:37:40Z" duration-ms="2" status="FAIL">
          <params>
            <param index="0">
              <value>
                <![CDATA[Akansha]]>
              </value>
            </param>
            <param index="1">
              <value>
                <![CDATA[Gupta]]>
              </value>
            </param>
          </params>
          <exception class="java.lang.AssertionError">
            <message>
              <![CDATA[expected [Gupta] but found [Akansha]]]>
            </message>
            <full-stacktrace>
              <![CDATA[java.lang.AssertionError: expected [Gupta] but found [Akansha]
at org.testng.Assert.fail(Assert.java:96)
at org.testng.Assert.failNotEquals(Assert.java:776)
at org.testng.Assert.assertEqualsImpl(Assert.java:137)
at org.testng.Assert.assertEquals(Assert.java:118)
at org.testng.Assert.assertEquals(Assert.java:453)
at org.testng.Assert.assertEquals(Assert.java:463)
at testNG_Example.RerunningFailedTestMethod.method4(RerunningFailedTestMethod.java:14)
at java.base/jdk.internal.reflect.NativeMethodAccessorImpl.invoke0(Native Method)
at java.base/jdk.internal.reflect.NativeMethodAccessorImpl.invoke(Unknown Source)
at java.base/jdk.internal.reflect.DelegatingMethodAccessorImpl.invoke(Unknown Source)
at java.base/java.lang.reflect.Method.invoke(Unknown Source)
at org.testng.internal.MethodInvocationHelper.invokeMethod(MethodInvocationHelper.java:124)
at org.testng.internal.Invoker.invokeMethod(Invoker.java:580)
at org.testng.internal.Invoker.invokeTestMethod(Invoker.java:716)
at org.testng.internal.Invoker.invokeTestMethods(Invoker.java:988)
at org.testng.internal.TestMethodWorker.invokeTestMethods(TestMethodWorker.java:125)
at org.testng.internal.TestMethodWorker.run(TestMethodWorker.java:109)
at org.testng.TestRunner.privateRun(TestRunner.java:648)
at org.testng.TestRunner.run(TestRunner.java:505)
at org.testng.SuiteRunner.runTest(SuiteRunner.java:455)
at org.testng.SuiteRunner.runSequentially(SuiteRunner.java:450)
at org.testng.SuiteRunner.privateRun(SuiteRunner.java:415)
at org.testng.SuiteRunner.run(SuiteRunner.java:364)
at org.testng.SuiteRunnerWorker.runSuite(SuiteRunnerWorker.java:52)
at org.testng.SuiteRunnerWorker.run(SuiteRunnerWorker.java:84)
at org.testng.TestNG.runSuitesSequentially(TestNG.java:1208)
at org.testng.TestNG.runSuitesLocally(TestNG.java:1137)
at org.testng.TestNG.runSuites(TestNG.java:1049)
at org.testng.TestNG.run(TestNG.java:1017)
at org.testng.remote.AbstractRemoteTestNG.run(AbstractRemoteTestNG.java:114)
at org.testng.remote.RemoteTestNG.initAndRun(RemoteTestNG.java:251)
at org.testng.remote.RemoteTestNG.main(RemoteTestNG.java:77)
]]>
            </full-stacktrace>
          </exception> <!-- java.lang.AssertionError -->
          <reporter-output>
            <line>
              <![CDATA[Your name is : Akansha Gupta]]>
            </line>
          </reporter-output>
        </test-method> <!-- method4 -->
        <test-method signature="method4(java.lang.String, java.lang.String)[pri:0, instance:testNG_Example.RerunningFailedTestMethod@445b295b]" started-at="2018-11-02T15:37:40Z" name="method4" data-provider="input" finished-at="2018-11-02T15:37:40Z" duration-ms="1" status="PASS">
          <params>
            <param index="0">
              <value>
                <![CDATA[Jitendra]]>
              </value>
            </param>
            <param index="1">
              <value>
                <![CDATA[Jitendra]]>
              </value>
            </param>
          </params>
          <reporter-output>
            <line>
              <![CDATA[Your name is : Jitendra Jitendra]]>
            </line>
          </reporter-output>
        </test-method> <!-- method4 -->
      </class> <!-- testNG_Example.RerunningFailedTestMethod -->
    </test> <!-- Default test -->
  </suite> <!-- Default suite -->
</testng-results>
